Workbook

Sheet FCFF & DCF
B2: Assumptions and important ratios
B3: Tax rate: | C3: 0.3
B4: LT growth rate | C4: 0.015
B5: Revenue growth rate | C5: 26-28: analyst consensus; then fade (row 28)
B6: COGS / Revenue | C6: 0.785
B7: General Cost growth rate | C7: 0.075
B8: WACC | C8: =WACC!C31 -> 0.070599294
B9: Annual Capex / Revenue | C9: 0.058
B10: Avg delta NWC | C10: 0.1
B11: Valuation date | C11: 46203
B13: Assumptions (you can instead always use analyst FC) | C13: 2021 | D13: 2022 | E13: 2023 | F13: 2024 | G13: 2025 | H13: Average
B14: Revenue growth rate (historical) | C14: =C27/22580-1 -> 0.35606732 | D14: =D27/C27-1 -> 0.31727629 | E14: =E27/D27-1 -> 0.16206768 | F14: =F27/E27-1 -> 0.012822154 | G14: =G27/F27-1 -> -0.072083079 | H14: =AVERAGE(C14:G14) -> 0.15523007
B15: COGS / Revenue | C15: =C29/C27 -> 0.81917048 | D15: =D29/D27 -> 0.83009793 | E15: =E29/E27 -> 0.80286738 | F15: =F29/F27 -> 0.78724749 | G15: =G29/G27 -> 0.80883521 | H15: =AVERAGE(C15:G15) -> 0.8096437
B16: COGS / Revenue growth rate | D16: =D15/C15-1 -> 0.013339657 | E16: =E15/D15-1 -> -0.032804017 | F16: =F15/E15-1 -> -0.019455138 | G16: =G15/F15-1 -> 0.027421778 | H16: =AVERAGE(C16:G16) -> -0.0028744299
B17: SG&A / Revenue | C17: =C32/C27 -> 0.075310255 | D17: =D32/D27 -> 0.048369902 | E17: =E32/E27 -> 0.054488821 | F17: =F32/F27 -> 0.057042951 | G17: =G32/G27 -> 0.055730857 | H17: =AVERAGE(C17:G17) -> 0.058188557
B18: CapEx / Revenue | C18: =C40/C27 -> 0.036936643 | D18: =D40/D27 -> 0.032354035 | E18: =E40/E27 -> 0.032471412 | F18: =F40/F27 -> 0.037136899 | G18: =G40/G27 -> 0.035776713 | H18: =AVERAGE(C18:G18) -> 0.03493514
B19: Depreciation / Revenue | C19: =C35/C27 -> 0.089124755 | D19: =D35/D27 -> 0.073930829 | E19: =E35/E27 -> 0.061038573 | F19: =F35/F27 -> 0.0626672 | G19: =G35/G27 -> 0.071439922 | H19: =AVERAGE(C19:G19) -> 0.071640256
B20: Depreciation / CapEx | C20: =C35/C40 -> 2.4129089 | D20: =D35/D40 -> 2.2850575 | E20: =E35/E40 -> 1.8797635 | F20: =F35/F40 -> 1.6874645 | G20: =G35/G40 -> 1.9968274 | H20: =AVERAGE(C20:G20) -> 2.0524044
B21: delta NWC / Revenue | C21: -2559 | D21: 91 | E21: 2258 | F21: 812 | G21: -1016 | H21: =AVERAGE(C21:G21) -> -82.8
B24: Free Cash Flow Calculation | E24: Historical | K24: Forecast | P24: TV
B25: In EURm | H25: 0.5 | I25: 1.5 | J25: 2.5 | K25: 3.5 | L25: 4.5 | M25: 5.5 | N25: 6.5 | O25: … | P25: 6.5
B26: year | C26: 2021 | D26: 2022 | E26: 2023 | F26: 2024 | G26: 2025 | H26: 2026E | I26: 2027E | J26: 2028E | K26: 2029E | L26: 2030E | M26: 2031E | N26: 2032E | P26: TV
B27: Revenue | C27: 30620 | D27: 40335 | E27: 46872 | F27: 47473 | G27: 44051 | H27: 45897 | I27: 48970 | J27: 51000 | K27: =J27*(1+K28) -> 52785 | L27: =K27*(1+L28) -> 54368.55 | M27: =L27*(1+M28) -> 55727.764 | N27: =M27*(1+N28) -> 56842.319 | P27: =N27*(1+$C$4) -> 57694.954
B28: Revenue Growth (in %) | C28: =C14 -> 0.35606732 | D28: =D27/C27-1 -> 0.31727629 | E28: =E27/D27-1 -> 0.16206768 | F28: =F27/E27-1 -> 0.012822154 | G28: =G27/F27-1 -> -0.072083079 | H28: =H27/G27-1 -> 0.041905973 | I28: =I27/H27-1 -> 0.066954267 | J28: =J27/I27-1 -> 0.041453951 | K28: 0.035 | L28: 0.03 | M28: 0.025 | N28: 0.02 | P28: =$C$4 -> 0.015
B29: COGS | C29: 25083 | D29: 33482 | E29: 37632 | F29: 37373 | G29: 35630 | H29: =H27-8950 -> 36947 | I29: =I27-10131 -> 38839 | J29: =J27-11346 -> 39654 | K29: =K27*$C$6 -> 41436.225 | L29: =L27*$C$6 -> 42679.312 | M29: =M27*$C$6 -> 43746.295 | N29: =N27*$C$6 -> 44621.22 | P29: =P27*$C$6 -> 45290.539
B30: Gross Profit | C30: =C27-C29 -> 5537 | D30: =D27-D29 -> 6853 | E30: =E27-E29 -> 9240 | F30: =F27-F29 -> 10100 | G30: =G27-G29 -> 8421 | H30: =H27-H29 -> 8950 | I30: =I27-I29 -> 10131 | J30: =J27-J29 -> 11346 | ... N30: =N27-N29 -> 12221.099 | P30: =P27-P29 -> 12404.415
B31: Gross Profit as % of Revenue | C31: =C30/C27 -> 0.18082952 | D31: =D30/D27 -> 0.16990207 | E31: =E30/E27 -> 0.19713262 | F31: =F30/F27 -> 0.21275251 | G31: =G30/G27 -> 0.19116479 | H31: =H30/H27 -> 0.19500185 | I31: =I30/I27 -> 0.20688176 | J31: =J30/J27 -> 0.22247059 | ... N31: =N30/N27 -> 0.215 | P31: =P30/P27 -> 0.215
B32: SG&A | C32: =C30-3231 -> 2306 | D32: =D30-4902 -> 1951 | E32: =E30-6686 -> 2554 | F32: =F30-7392 -> 2708 | G32: =G30-5966 -> 2455 | H32: =H30-5719 -> 3231 | I32: =I30-6723 -> 3408 | J32: =J30-7486 -> 3860 | K32: =K27*$C$7 -> 3958.875 | L32: =L27*$C$7 -> 4077.6413 | M32: =M27*$C$7 -> 4179.5823 | N32: =N27*$C$7 -> 4263.1739 | P32: =P27*$C$7 -> 4327.1215
B33: EBITDA | C33: =C30-C32 -> 3231 | D33: =D30-D32 -> 4902 | E33: =E30-E32 -> 6686 | F33: =F30-F32 -> 7392 | G33: =G30-G32 -> 5966 | H33: =H30-H32 -> 5719 | I33: =I30-I32 -> 6723 | J33: =J30-J32 -> 7486 | ... N33: =N30-N32 -> 7957.9247 | P33: =P30-P32 -> 8077.2935
B34: EBITDA % margin | C34: =C33/C27 -> 0.10551927 | D34: =D33/D27 -> 0.12153217 | E34: =E33/E27 -> 0.1426438 | F34: =F33/F27 -> 0.15570956 | G34: =G33/G27 -> 0.13543393 | H34: =H33/H27 -> 0.12460509 | I34: =I33/I27 -> 0.13728814 | J34: =J33/J27 -> 0.14678431 | ... N34: =N33/N27 -> 0.14 | P34: =P33/P27 -> 0.14
B35: Depreciation | C35: 2729 | D35: 2982 | E35: 2861 | F35: 2975 | G35: 3147 | H35: =H33-3049 -> 2670 | I35: =I33-3986 -> 2737 | J35: =J33-4529 -> 2957 | K35: =K27*0.058 -> 3061.53 | L35: =L27*0.058 -> 3153.3759 | M35: =M27*0.058 -> 3232.2103 | N35: =N27*0.058 -> 3296.8545 | P35: =P27*0.058 -> 3346.3073
B36: EBIT | C36: =C33-C35 -> 502 | D36: =D33-D35 -> 1920 | E36: =E33-E35 -> 3825 | F36: =F33-F35 -> 4417 | G36: =G33-G35 -> 2819 | H36: =H33-H35 -> 3049 | I36: =I33-I35 -> 3986 | J36: =J33-J35 -> 4529 | ... N36: =N33-N35 -> 4661.0702 | P36: =P33-P35 -> 4730.9862
B37: EBIT % margin | C37: =C36/C27 -> 0.016394513 | D37: =D36/D27 -> 0.047601339 | E37: =E36/E27 -> 0.081605223 | F37: =F36/F27 -> 0.093042361 | G37: =G36/G27 -> 0.063994007 | H37: =H36/H27 -> 0.066431357 | I37: =I36/I27 -> 0.081396774 | J37: =J36/J27 -> 0.088803922 | ... N37: =N36/N27 -> 0.082 | P37: =P36/P27 -> 0.082
B38: Taxes paid | C38: =C36*$C$3 -> 150.6 | D38: =D36*$C$3 -> 576 | E38: =E36*$C$3 -> 1147.5 | F38: =F36*$C$3 -> 1325.1 | G38: =G36*$C$3 -> 845.7 | H38: =H36*$C$3 -> 914.7 | I38: =I36*$C$3 -> 1195.8 | J38: =J36*$C$3 -> 1358.7 | ... N38: =N36*$C$3 -> 1398.321 | P38: =P36*$C$3 -> 1419.2959
B39: Net Income | C39: =C36-C38 -> 351.4 | D39: =D36-D38 -> 1344 | E39: =E36-E38 -> 2677.5 | F39: =F36-F38 -> 3091.9 | G39: =G36-G38 -> 1973.3 | H39: =H36-H38 -> 2134.3 | I39: =I36-I38 -> 2790.2 | J39: =J36-J38 -> 3170.3 | ... N39: =N36-N38 -> 3262.7491 | P39: =P36-P38 -> 3311.6903
B40: CapEx | C40: 1131 | D40: 1305 | E40: 1522 | F40: 1763 | G40: 1576 | H40: 2665 | I40: 2667 | J40: 2764 | K40: =K27*$C$9 -> 3061.53 | L40: =L27*$C$9 -> 3153.3759 | M40: =M27*$C$9 -> 3232.2103 | N40: =N27*$C$9 -> 3296.8545 | P40: =P35 -> 3346.3073
B41: Depreciation | C41: =C35 -> 2729 | D41: =D35 -> 2982 | E41: =E35 -> 2861 | F41: =F35 -> 2975 | G41: =G35 -> 3147 | H41: =H35 -> 2670 | I41: =I35 -> 2737 | J41: =J35 -> 2957 | ... N41: =N35 -> 3296.8545 | P41: =P35 -> 3346.3073
B42: delta Net Working Capital | C42: =C21 -> -2559 | D42: =D21 -> 91 | E42: =E21 -> 2258 | F42: =F21 -> 812 | G42: =G21 -> -1016 | H42: =(H27-G27)*$C$10 -> 184.6 | I42: =(I27-H27)*$C$10 -> 307.3 | J42: =(J27-I27)*$C$10 -> 203 | K42: =(K27-J27)*$C$10 -> 178.5 | L42: =(L27-K27)*$C$10 -> 158.355 | M42: =(M27-L27)*$C$10 -> 135.92138 | N42: =(N27-M27)*$C$10 -> 111.45553 | P42: =(P27-N27)*$C$10 -> 85.263479
B43: Free Cash Flow | C43: =C39+C41-C40-C42 -> 4508.4 | D43: =D39+D41-D40-D42 -> 2930 | E43: =E39+E41-E40-E42 -> 1758.5 | F43: =F39+F41-F40-F42 -> 3491.9 | G43: =G39+G41-G40-G42 -> 4560.3 | H43: =H39+H41-H40-H42 -> 1954.7 | I43: =I39+I41-I40-I42 -> 2552.9 | J43: =J39+J41-J40-J42 -> 3160.3 | ... N43: =N39+N41-N40-N42 -> 3151.2936 | P43: =P39+P41-P40-P42 -> 3226.4269
G46: Discounted CF | H46: =H43*0.5/(1+$C$8)^H25 -> 944.57542 | I46: =I43/(1+$C$8)^I25 -> 2304.5884 | J46: =J43/(1+$C$8)^J25 -> 2664.7774 | K46: =K43/(1+$C$8)^K25 -> 2245.7301 | L46: =L43/(1+$C$8)^L25 -> 2179.3269 | M46: =M43/(1+$C$8)^M25 -> 2104.6399 | N46: =N43/(1+$C$8)^N25 -> 2022.6171
...

Sheet WACC
B2: Cost of Equity: | F2: Peer | H2: Adj. Beta | I2: Net debt | J2: Tax-rate | K2: Equity | L2: D/E | M2: Unlevered Beta
F3: Volvo AB (B) | H3: 0.92 | I3: -44058 | J3: 0.206 | K3: 669572 | L3: =I3/K3 -> -0.065800243 | M3: =H3/(1+(1-J3)*L3) -> 0.97071541
B4: Risk-free rate | C4: 0.029 | F4: Daimler Truck | H4: 0.94 | I4: -9161 | J4: 0.3 | K4: 32431 | L4: =I4/K4 -> -0.28247664 | M4: =H4/(1+(1-J4)*L4) -> 1.1716807
B5: Equity market premium (Germany): | C5: 0.0423 | F5: (Traton own, memo) | H5: 1.23
B6: Debt / Capital Ratio | C6: =C26 -> 0.23731151 | F6: Peer average | G6: =AVERAGE(M3:M4) -> 1.0711981
B7: Re-levered beta: | C7: =G6*(1+(1-C29)*C28) -> 1.3045113
B10: Cost of Equity (CAPM): | C10: =C4+C7*C5 -> 0.084180829
B12: Cost of Debt:
B13: CDS spread (5Y) | C13: 0.0095
B14: Risk-free rate | C14: =C4 -> 0.029
B15: Pre-tax cost of debt | C15: =C13+C14 -> 0.0385
B16: Tax rate | C16: 0.3
B17: After-tax cost of debt | C17: =C15*(1-C16) -> 0.02695
B20: Cost of Debt: | C20: =C17 -> 0.02695
B22: WACC:
B24: Equity market value | C24: 16590
B25: Net debt incl. EV adj. | C25: 5162
B26: Debt / Capital | C26: =C25/(C24+C25) -> 0.23731151
B27: Equity / Capital | C27: =C24/(C24+C25) -> 0.76268849
B28: Target D/E | C28: =C25/C24 -> 0.3111513
B29: Tax rate | C29: 0.3
B31: WACC | C31: =C27*C10+C26*C17 -> 0.070599294

Sheet Equity Bridge
B2: Equity Bridge:
B5: Firm Value | C5: ='FCFF & DCF'!H50 -> 51712.059
B6: + Cash & Securities | C6: 2277
B7: - Debt | C7: 7439
B8: - Pensions | C8: 1644
B9: - Minority Interest | C9: 3
B10: - Value of Preferred Stocks | C10: 0
B11: Equity Value | C11: =C5+C6-C7-C8-C9-C10 -> 44903.059
B13: Number of outstanding shares (in m) | C13: 500
B14: Implied share price | C14: =C11/C13 -> 89.806119
B16: Current share price (30.06.2026) | C16: 33.18
B17: Implied upside | C17: =C14/C16-1 -> 1.7066341

Sheet Multiples
D6: Financial Data | P6: Valuation
C7: EV | D7: EBITDA | H7: Revenue | L7: EBIT | P7: EV/EBITDA | T7: EV/Revenue | X7: EV/EBIT
B8: Company Name | D8: (€M) | H8: (€M) | L8: (€M) | P8: x | T8: x | X8: x
C9: (€M) | D9: LFY | E9: LTM | F9: FY+1 | G9: FY+2 | H9: LFY | I9: LTM | J9: FY+1 | K9: FY+2 | L9: LFY | M9: LTM | N9: FY+1 | O9: FY+2 | P9: LFY | Q9: LTM | R9: FY+1 | S9: FY+2 | T9: LFY | U9: LTM | V9: FY+1 | W9: FY+2 | X9: LFY | Y9: LTM | Z9: FY+1 | AA9: FY+2
B10: Volvo AB (B) | C10: 56773 | D10: 6885 | E10: 6304 | F10: 7128 | G10: 7989 | H10: 43483 | I10: 42482 | J10: 44622 | K10: 47938 | L10: 4886 | M10: 4161 | N10: 5119 | O10: 6060 | P10: =$C10/D10 -> 8.2458969 | Q10: =$C10/E10 -> 9.0058693 | R10: =$C10/F10 -> 7.9647868 | S10: =$C10/G10 -> 7.1063963 | T10: =$C10/H10 -> 1.3056367 | U10: =$C10/I10 -> 1.3364013 | V10: =$C10/J10 -> 1.2723096 | W10: =$C10/K10 -> 1.1843006 | X10: =IF(ISNUMBER(L10),$C10/L10,"n/a") -> 11.619525 | Y10: =IF(ISNUMBER(M10),$C10/M10,"n/a") -> 13.644076 | Z10: =IF(ISNUMBER(N10),$C10/N10,"n/a") -> 11.090643 | AA10: =IF(ISNUMBER(O10),$C10/O10,"n/a") -> 9.3684818
B11: Daimler Truck | C11: 23813 | D11: 4403 | E11: 4049 | F11: 4643 | G11: 5850 | H11: 45530 | I11: 44003 | J11: 48685 | K11: 52583 | L11: 3328 | M11: 3015 | N11: 3551 | O11: 4695 | P11: =$C11/D11 -> 5.4083579 | Q11: =$C11/E11 -> 5.8812052 | R11: =$C11/F11 -> 5.128796 | S11: =$C11/G11 -> 4.0705983 | T11: =$C11/H11 -> 0.52301779 | U11: =$C11/I11 -> 0.54116765 | V11: =$C11/J11 -> 0.48912396 | W11: =$C11/K11 -> 0.45286499 | X11: =IF(ISNUMBER(L11),$C11/L11,"n/a") -> 7.1553486 | Y11: =IF(ISNUMBER(M11),$C11/M11,"n/a") -> 7.8981758 | Z11: =IF(ISNUMBER(N11),$C11/N11,"n/a") -> 6.7059983 | AA11: =IF(ISNUMBER(O11),$C11/O11,"n/a") -> 5.0719915
B12: Iveco Group | C12: 1241 | D12: 1378 | E12: 1169 | F12: 1609 | G12: 1842 | H12: 13428 | I12: 13230 | J12: 14920 | K12: 16258 | L12: n/a | M12: n/a | N12: n/a | O12: n/a | P12: =$C12/D12 -> 0.90058055 | Q12: =$C12/E12 -> 1.0615911 | R12: =$C12/F12 -> 0.77128651 | S12: =$C12/G12 -> 0.67372421 | T12: =$C12/H12 -> 0.092418826 | U12: =$C12/I12 -> 0.093801965 | V12: =$C12/J12 -> 0.083176944 | W12: =$C12/K12 -> 0.076331652 | X12: =IF(ISNUMBER(L12),$C12/L12,"n/a") -> n/a | Y12: =IF(ISNUMBER(M12),$C12/M12,"n/a") -> n/a | Z12: =IF(ISNUMBER(N12),$C12/N12,"n/a") -> n/a | AA12: =IF(ISNUMBER(O12),$C12/O12,"n/a") -> n/a
D14: Financial Data | P14: Implied Enterprise value
C15: EV | D15: EBITDA | H15: Revenue | L15: EBIT | P15: EV/EBITDA | T15: EV/Revenue | X15: EV/EBIT
B16: Company Name | D16: (€M) | H16: (€M) | L16: (€M) | P16: x | T16: x | X16: x
C17: (€M) | D17: LFY | E17: LTM | F17: FY+1 | G17: FY+2 | H17: LFY | I17: LTM | J17: FY+1 | K17: FY+2 | L17: LFY | M17: LTM | N17: FY+1 | O17: FY+2 | P17: LFY | Q17: LTM | R17: FY+1 | S17: FY+2 | T17: LFY | U17: LTM | V17: FY+1 | W17: FY+2 | X17: LFY | Y17: LTM | Z17: FY+1 | AA17: FY+2
B18: Traton | C18: 20759 | D18: 5966 | E18: 6072 | F18: 5719 | G18: 6723 | H18: 44051 | I18: 43675 | J18: 45897 | K18: 48970 | L18: 2819 | M18: 2731 | N18: 3049 | O18: 3986 | P18: =MEDIAN(P10:P12)*D18 -> 32266.263 | Q18: =MEDIAN(Q10:Q12)*E18 -> 35710.678 | R18: =MEDIAN(R10:R12)*F18 -> 29331.585 | S18: =MEDIAN(S10:S12)*G18 -> 27366.632 | T18: =MEDIAN(T10:T12)*H18 -> 23039.457 | U18: =MEDIAN(U10:U12)*I18 -> 23635.497 | V18: =MEDIAN(V10:V12)*J18 -> 22449.322 | W18: =MEDIAN(W10:W12)*K18 -> 22176.799 | X18: =MEDIAN(X10:X11)*L18 -> 26463.185 | Y18: =MEDIAN(Y10:Y11)*M18 -> 29415.945 | Z18: =MEDIAN(Z10:Z11)*N18 -> 27130.979 | AA18: =MEDIAN(AA10:AA11)*O18 -> 28779.863
B20: Comparison: Company vs. Peer Group
C21: EV | D21: EBITDA | H21: Revenue | L21: EBIT | P21: EV/EBITDA | T21: EV/Revenue | X21: EV/EBIT
B22: Traton | P22: =$C$18/D18 -> 3.4795508 | Q22: =$C$18/E18 -> 3.4188076 | R22: =$C$18/F18 -> 3.6298304 | S22: =$C$18/G18 -> 3.0877584 | T22: =$C$18/H18 -> 0.47124923 | U22: =$C$18/I18 -> 0.47530624 | V22: =$C$18/J18 -> 0.45229536 | W22: =$C$18/K18 -> 0.4239126 | ... AA22: =$C$18/O18 -> 5.2079779
B23: Quartile 1 | P23: =QUARTILE(P10:P12,1) -> 3.1544692 | Q23: =QUARTILE(Q10:Q12,1) -> 3.4713982 | R23: =QUARTILE(R10:R12,1) -> 2.9500413 | S23: =QUARTILE(S10:S12,1) -> 2.3721613 | T23: =QUARTILE(T10:T12,1) -> 0.30771831 | U23: =QUARTILE(U10:U12,1) -> 0.31748481 | V23: =QUARTILE(V10:V12,1) -> 0.28615045 | W23: =QUARTILE(W10:W12,1) -> 0.26459832 | X23: =QUARTILE(X10:X11,1) -> 8.2713927 | Y23: =QUARTILE(Y10:Y11,1) -> 9.3346508 | Z23: =QUARTILE(Z10:Z11,1) -> 7.8021594 | AA23: =QUARTILE(AA10:AA11,1) -> 6.1461141
B24: Average | P24: =AVERAGE(P10:P12) -> 4.8516118 | Q24: =AVERAGE(Q10:Q12) -> 5.3162219 | R24: =AVERAGE(R10:R12) -> 4.6216231 | S24: =AVERAGE(S10:S12) -> 3.9502396 | T24: =AVERAGE(T10:T12) -> 0.64035777 | U24: =AVERAGE(U10:U12) -> 0.65712364 | V24: =AVERAGE(V10:V12) -> 0.61487018 | W24: =AVERAGE(W10:W12) -> 0.57116573 | X24: =AVERAGE(X10:X11) -> 9.3874369 | Y24: =AVERAGE(Y10:Y11) -> 10.771126 | Z24: =AVERAGE(Z10:Z11) -> 8.8983205 | AA24: =AVERAGE(AA10:AA11) -> 7.2202367
B25: Median | P25: =MEDIAN(P10:P12) -> 5.4083579 | Q25: =MEDIAN(Q10:Q12) -> 5.8812052 | R25: =MEDIAN(R10:R12) -> 5.128796 | S25: =MEDIAN(S10:S12) -> 4.0705983 | T25: =MEDIAN(T10:T12) -> 0.52301779 | U25: =MEDIAN(U10:U12) -> 0.54116765 | V25: =MEDIAN(V10:V12) -> 0.48912396 | W25: =MEDIAN(W10:W12) -> 0.45286499 | X25: =MEDIAN(X10:X11) -> 9.3874369 | Y25: =MEDIAN(Y10:Y11) -> 10.771126 | Z25: =MEDIAN(Z10:Z11) -> 8.8983205 | AA25: =MEDIAN(AA10:AA11) -> 7.2202367
B26: Quartile 3 | P26: =QUARTILE(P10:P12,3) -> 6.8271274 | Q26: =QUARTILE(Q10:Q12,3) -> 7.4435373 | R26: =QUARTILE(R10:R12,3) -> 6.5467914 | S26: =QUARTILE(S10:S12,3) -> 5.5884973 | T26: =QUARTILE(T10:T12,3) -> 0.91432724 | U26: =QUARTILE(U10:U12,3) -> 0.93878447 | V26: =QUARTILE(V10:V12,3) -> 0.88071679 | W26: =QUARTILE(W10:W12,3) -> 0.81858277 | X26: =QUARTILE(X10:X11,3) -> 10.503481 | Y26: =QUARTILE(Y10:Y11,3) -> 12.207601 | Z26: =QUARTILE(Z10:Z11,3) -> 9.9944816 | AA26: =QUARTILE(AA10:AA11,3) -> 8.2943593
B28: Implied equity value per share (equity bridge: net adjustments -6,809 EURm)
B29: EV/EBITDA FY+1 (median) | C29: =(R18+'Equity Bridge'!$C$6-'Equity Bridge'!$C$7-'Equity Bridge'!$C$8-'Equity Bridge'!$C$9)/'Equity Bridge'!$C$13 -> 45.045169
B30: EV/EBITDA FY+2 (median) | C30: =(S18+'Equity Bridge'!$C$6-'Equity Bridge'!$C$7-'Equity Bridge'!$C$8-'Equity Bridge'!$C$9)/'Equity Bridge'!$C$13 -> 41.115265
B31: EV/Revenue FY+1 (median) | C31: =(V18+'Equity Bridge'!$C$6-'Equity Bridge'!$C$7-'Equity Bridge'!$C$8-'Equity Bridge'!$C$9)/'Equity Bridge'!$C$13 -> 31.280645
B32: EV/EBIT FY+1 (median) | C32: =(Z18+'Equity Bridge'!$C$6-'Equity Bridge'!$C$7-'Equity Bridge'!$C$8-'Equity Bridge'!$C$9)/'Equity Bridge'!$C$13 -> 40.643958
B34: P/E FY+1 (peer median x Traton EPS 2026E) | C34: =MEDIAN(15.4,12.81)*4.2 -> 59.241

Sheet Football-Field
I3: Valuation | J3: low | K3: diff | L3: high | N3: Current price (30/06/2026)
I4: 52-week trading range | J4: 25.78 | K4: =L4-J4 -> 11.56 | L4: 37.34 | N4: 33.18
I5: Analyst price targets | J5: 23 | K5: =L5-J5 -> 25 | L5: 48
I6: DCF (WACC 6.5-7.5%, g 1.0-2.0%) | J6: ='FCFF & DCF'!K58/'Equity Bridge'!$C$13 -> 77.158388 | K6: =L6-J6 -> 33.589628 | L6: ='FCFF & DCF'!M56/'Equity Bridge'!$C$13 -> 110.74802
I7: Multiples (EV/EBITDA FY+1, DTG-Volvo) | J7: =(Multiples!R11*Multiples!F18+'Equity Bridge'!$C$6-'Equity Bridge'!$C$7-'Equity Bridge'!$C$8-'Equity Bridge'!$C$9)/'Equity Bridge'!$C$13 -> 45.045169 | K7: =L7-J7 -> 32.438062 | L7: =(Multiples!R10*Multiples!F18+'Equity Bridge'!$C$6-'Equity Bridge'!$C$7-'Equity Bridge'!$C$8-'Equity Bridge'!$C$9)/'Equity Bridge'!$C$13 -> 77.483231

Sheet Data Notes (A1-A3)
B2: Supplementary data notes for additional questions A.1-A.3
B4: A.1 - Debt structure across peers (EURm unless noted)
C5: Traton | D5: Volvo (SEKm) | E5: Daimler Truck
B6: Total debt (incl. Financial Services) | C6: 28799 | D6: 257633 | E6: 29921
B7: Cash & equivalents | C7: 3005 | D7: 72573 | E7: 12903
B8: Net debt, total group | C8: 25794 | D8: 185060 | E8: 17018
B9: Net debt, industrial (Bloomberg EV-adj.) | C9: 4009 | D9: -44058 | E9: -9161
B10: FS receivables funded by FS debt | C10: 17906 | D10: large | E10: large
B11: Net debt / EBITDA (industrial, LTM) | C11: 0.66 | D11: -0.63 | E11: -2.26
B13: Note: all three oems run captive finance units. traton is the only one with industrial net debt (navistar acquisition 2021, debt-financed); volvo and daimler truck hold industrial net cash. unadjusted evs would overstate traton ev by ~22bn; bloomberg-adjusted evs used throughout.
B16: A.2 - Business line evidence (LSEG segment data / factsheet, FY2025, EURm)
C17: Revenue | D17: Op. profit | E17: RoS adj.
B18: Scania Vehicles & Services | C18: 17945 | D18: 1926 | E18: 10.7%
B19: MAN Truck & Bus | C19: 14095 | D19: 904 | E19: 6.4%
B20: International Motors | C20: 8169 | D20: 9 | E20: 0.1%
B21: Volkswagen Truck & Bus | C21: 2768 | D21: 323 | E21: 11.7%
B22: TRATON Financial Services | C22: 2188 | D22: 167 | E22: 8.2%
B24: Note: synergy levers: traton modular system (common base engine, shared powertrains scania->man/international), centralized r&d since 2025 reorganization (segment figures restated), joint procurement, one group-wide fs captive, milence charging jv. margin spread scania 10.7% vs international 0.1% shows integration potential not yet realized.
B27: A.3 - Bloomberg vs. LSEG consensus, Traton (EURm)
C28: Bloomberg | D28: LSEG | E28: Delta
B29: Revenue 2026E | C29: 45897 | D29: 45755 | E29: -0.3%
B30: Revenue 2027E | C30: 48970 | D30: 48661 | E30: -0.6%
B31: EBITDA 2026E | C31: 5719 | D31: 5802 | E31: +1.4%
B32: EBITDA 2027E | C32: 6723 | D32: 6746 | E32: +0.3%
B33: EPS 2026E | C33: 4.2 | D33: 4.22 | E33: +0.5%
B34: Net debt 2026E | C34: 4,009 (industrial) | D34: 15,601 (group def.) | E34: n/m
B36: Note: p&l consensus differs by <2% (different contributor panels / adjustment logic) - negligible for multiples. debt/ev definitions differ massively (treatment of financial services): the net debt definition moves implied equity value by >10 eur/share - this, not p&l data, is the decisive data issue.
B39: Sources used
B40: Bloomberg: XCVA_TRATON (CompVal), XCSF Tearsheets, 8TRA/VOLVO/DAIMLER_EST.pdf (03/07/2026); LSEG business-line estimates (03/07/2026); Traton AR 2025 (p.62/65), factsheet 29/06/2026; PRICE_HISTORY (30/06/2026); Yahoo Finance betas; Bundesbank/TradingEconomics 10Y Bund ~2.9%; EUR/SEK 11.02 (LSEG-implied; ECB 11.09).
