Workbook

Sheet FCFF & DCF
B2: Assumptions and important ratios
B3: Tax rate: | C3: 0.3
B4: LT growth rate | C4: 0.015
B5: Revenue growth rate | C5: 0.03
B6: COGS / Revenue | C6: 0.75
B7: General Cost growth rate | C7: 0.03
B8: WACC | C8: =WACC!C31 -> 0.060405777
B9: Annual Capex / Revenue | C9: 0.06
B10: Avg delta NWC | C10: 0.01
B11: Valuation date | C11: 46203
B13: Assumptions (you can instead always use analyst FC) | C13: 2021 | D13: 2022 | E13: 2023 | F13: 2024 | G13: 2025 | H13: Average
B14: Revenue growth rate (historical) | D14: =D27/C27-1 -> 0.31727629 | E14: =E27/D27-1 -> 0.16206768 | F14: =F27/E27-1 -> 0.012822154 | G14: =G27/F27-1 -> -0.072062014 | H14: =AVERAGE(C14:G14) -> 0.10502603
B15: COGS / Revenue | C15: =C29/C27 -> 0.76861528 | D15: =D29/D27 -> 0.76891038 | E15: =E29/E27 -> 0.74940263 | F15: =F29/F27 -> 0.73233206 | G15: =G29/G27 -> 0.74909198 | H15: =AVERAGE(C15:G15) -> 0.75367047
B16: COGS / Revenue growth rate | D16: =D15/C15-1 -> 0.00038392611 | E16: =E15/D15-1 -> -0.025370638 | F16: =F15/E15-1 -> -0.022778898 | G16: =G15/F15-1 -> 0.022885683 | H16: =AVERAGE(C16:G16) -> -0.0062199817
B17: SG&A / Revenue | C17: =C32/C27 -> 0.12939255 | D17: =D32/D27 -> 0.11838354 | E17: =E32/E27 -> 0.10927633 | F17: =F32/F27 -> 0.11633981 | G17: =G32/G27 -> 0.12439844 | H17: =AVERAGE(C17:G17) -> 0.11955813
B18: CapEx / Revenue | C18: =C40/C27 -> 0.052253429 | D18: =D40/D27 -> 0.047105492 | E18: =E40/E27 -> 0.046936337 | F18: =F40/F27 -> 0.057695953 | G18: =G40/G27 -> 0.063583946 | H18: =AVERAGE(C18:G18) -> 0.053515032
B19: Depreciation / Revenue | C19: =C35/C27 -> 0.089124755 | D19: =D35/D27 -> 0.073930829 | E19: =E35/E27 -> 0.061038573 | F19: =F35/F27 -> 0.0626672 | G19: =G35/G27 -> 0.0714383 | H19: =AVERAGE(C19:G19) -> 0.071639932
B20: Depreciation / CapEx | C20: =C35/C40 -> 1.705625 | D20: =D35/D40 -> 1.5694737 | E20: =E35/E40 -> 1.3004545 | F20: =F35/F40 -> 1.0861628 | G20: =G35/G40 -> 1.1235273 | H20: =AVERAGE(C20:G20) -> 1.3570487
B21: delta NWC / Revenue | C21: =C42/C27 -> 0 | D21: =D42/D27 -> 0.0023056898 | E21: =E42/E27 -> 0.048195084 | F21: =F42/F27 -> 0.017104459 | G21: =G42/G27 -> -0.023109053 | H21: =AVERAGE(C21:G21) -> 0.0088992362
B24: Free Cash Flow Calculation | E24: Historical | K24: Forecast | P24: TV
B25: In EURm | H25: 0 | I25: 1 | J25: 2 | K25: 3 | L25: 4 | M25: 5 | N25: 6 | O25: … | P25: X
B26: year | C26: 2021 | D26: 2022 | E26: 2023 | F26: 2024 | G26: 2025 | H26: 2026E | I26: 2027E | J26: 2028E | K26: 2029E | L26: 2030E | M26: 2031E | N26: 2032E | P26: TV
B27: Revenue | C27: 30620 | D27: 40335 | E27: 46872 | F27: 47473 | G27: 44052 | H27: =G27*(1+H28) -> 45770.028 | I27: =H27*(1+I28) -> 48699.31 | J27: =I27*(1+J28) -> 51036.877 | K27: =J27*(1+K28) -> 52823.167 | L27: =K27*(1+L28) -> 54407.862 | M27: =L27*(1+M28) -> 55768.059 | N27: =M27*(1+N28) -> 56883.42
B28: Revenue Growth (in %) | D28: =D27/C27-1 -> 0.31727629 | E28: =E27/D27-1 -> 0.16206768 | F28: =F27/E27-1 -> 0.012822154 | G28: =G27/F27-1 -> -0.072062014 | H28: 0.039 | I28: 0.064 | J28: 0.048 | K28: 0.035 | L28: 0.03 | M28: 0.025 | N28: 0.02
B29: COGS | C29: 23535 | D29: 31014 | E29: 35126 | F29: 34766 | G29: 32999 | H29: =H27*$C$6 -> 34327.521 | I29: =I27*$C$6 -> 36524.482 | J29: =J27*$C$6 -> 38277.657 | K29: =K27*$C$6 -> 39617.376 | L29: =L27*$C$6 -> 40805.897 | M29: =M27*$C$6 -> 41826.044 | N29: =N27*$C$6 -> 42662.565
B30: Gross Profit | C30: =C27-C29 -> 7085 | D30: =D27-D29 -> 9321 | E30: =E27-E29 -> 11746 | F30: =F27-F29 -> 12707 | G30: =G27-G29 -> 11053 | H30: =H27-H29 -> 11442.507 | I30: =I27-I29 -> 12174.827 | J30: =J27-J29 -> 12759.219 | ... N30: =N27-N29 -> 14220.855
B31: Gross Profit as % of Revenue | C31: =C30/C27 -> 0.23138472 | D31: =D30/D27 -> 0.23108962 | E31: =E30/E27 -> 0.25059737 | F31: =F30/F27 -> 0.26766794 | G31: =G30/G27 -> 0.25090802 | H31: =H30/H27 -> 0.25 | I31: =I30/I27 -> 0.25 | J31: =J30/J27 -> 0.25 | ... N31: =N30/N27 -> 0.25
B32: SG&A | C32: 3962 | D32: 4775 | E32: 5122 | F32: 5523 | G32: 5480 | H32: =G32*(1+$C$7) -> 5644.4 | I32: =H32*(1+$C$7) -> 5813.732 | J32: =I32*(1+$C$7) -> 5988.144 | K32: =J32*(1+$C$7) -> 6167.7883 | L32: =K32*(1+$C$7) -> 6352.8219 | M32: =L32*(1+$C$7) -> 6543.4066 | N32: =M32*(1+$C$7) -> 6739.7088
B33: EBITDA | C33: =C30-C32 -> 3123 | D33: =D30-D32 -> 4546 | E33: =E30-E32 -> 6624 | F33: =F30-F32 -> 7184 | G33: =G30-G32 -> 5573 | H33: =H30-H32 -> 5798.107 | I33: =I30-I32 -> 6361.0954 | J33: =J30-J32 -> 6771.0752 | ... N33: =N30-N32 -> 7481.1462
B34: EBITDA % margin | C34: =C33/C27 -> 0.10199216 | D34: =D33/D27 -> 0.11270609 | E34: =E33/E27 -> 0.14132104 | F34: =F33/F27 -> 0.15132812 | G34: =G33/G27 -> 0.12650958 | H34: =H33/H27 -> 0.12667912 | I34: =I33/I27 -> 0.13061983 | J34: =J33/J27 -> 0.13267025 | ... N34: =N33/N27 -> 0.13151717
B35: Depreciation | C35: 2729 | D35: 2982 | E35: 2861 | F35: 2975 | G35: 3147 | H35: =H27*$H$19 -> 3278.9617 | I35: =I27*$H$19 -> 3488.8152 | J35: =J27*$H$19 -> 3656.2784 | K35: =K27*$H$19 -> 3784.2481 | L35: =L27*$H$19 -> 3897.7755 | M35: =M27*$H$19 -> 3995.2199 | N35: =N27*$H$19 -> 4075.1243
B36: EBIT | C36: =C33-C35 -> 394 | D36: =D33-D35 -> 1564 | E36: =E33-E35 -> 3763 | F36: =F33-F35 -> 4209 | G36: =G33-G35 -> 2426 | H36: =H33-H35 -> 2519.1453 | I36: =I33-I35 -> 2872.2802 | J36: =J33-J35 -> 3114.7969 | ... N36: =N33-N35 -> 3406.0219
B37: EBIT % margin | C37: =C36/C27 -> 0.012867407 | D37: =D36/D27 -> 0.038775257 | E37: =E36/E27 -> 0.080282471 | F37: =F36/F27 -> 0.088660923 | G37: =G36/G27 -> 0.055071279 | H37: =H36/H27 -> 0.055039191 | I37: =I36/I27 -> 0.058979896 | J37: =J36/J27 -> 0.061030319 | ... N37: =N36/N27 -> 0.059877235
B38: Taxes paid | C38: =C36*$C$3 -> 118.2 | D38: =D36*$C$3 -> 469.2 | E38: =E36*$C$3 -> 1128.9 | F38: =F36*$C$3 -> 1262.7 | G38: =G36*$C$3 -> 727.8 | H38: =H36*$C$3 -> 755.7436 | I38: =I36*$C$3 -> 861.68407 | J38: =J36*$C$3 -> 934.43906 | ... N38: =N36*$C$3 -> 1021.8066
B39: Net Income | C39: =C36-C38 -> 275.8 | D39: =D36-D38 -> 1094.8 | E39: =E36-E38 -> 2634.1 | F39: =F36-F38 -> 2946.3 | G39: =G36-G38 -> 1698.2 | H39: =H36-H38 -> 1763.4017 | I39: =I36-I38 -> 2010.5962 | J39: =J36-J38 -> 2180.3578 | ... N39: =N36-N38 -> 2384.2153
B40: CapEx | C40: 1600 | D40: 1900 | E40: 2200 | F40: 2739 | G40: 2801 | H40: =H27*$C$9 -> 2746.2017 | I40: =I27*$C$9 -> 2921.9586 | J40: =J27*$C$9 -> 3062.2126 | K40: =K27*$C$9 -> 3169.39 | L40: =L27*$C$9 -> 3264.4717 | M40: =M27*$C$9 -> 3346.0835 | N40: =N27*$C$9 -> 3413.0052
B41: Depreciation | C41: =C35 -> 2729 | D41: =D35 -> 2982 | E41: =E35 -> 2861 | F41: =F35 -> 2975 | G41: =G35 -> 3147 | H41: =H35 -> 3278.9617 | I41: =I35 -> 3488.8152 | J41: =J35 -> 3656.2784 | ... N41: =N35 -> 4075.1243
B42: delta Net Working Capital | C42: 0 | D42: 93 | E42: 2259 | F42: 812 | G42: -1018 | H42: =$C$10*(H27-G27) -> 17.18028 | I42: =$C$10*(I27-H27) -> 29.292818 | J42: =$C$10*(J27-I27) -> 23.375669 | K42: =$C$10*(K27-J27) -> 17.862907 | L42: =$C$10*(L27-K27) -> 15.84695 | M42: =$C$10*(M27-L27) -> 13.601966 | N42: =$C$10*(N27-M27) -> 11.153612
B43: Free Cash Flow | C43: =C39+C41-C40-C42 -> 1404.8 | D43: =D39+D41-D40-D42 -> 2083.8 | E43: =E39+E41-E40-E42 -> 1036.1 | F43: =F39+F41-F40-F42 -> 2370.3 | G43: =G39+G41-G40-G42 -> 3062.2 | H43: =H39+H41-H40-H42 -> 2278.9814 | I43: =I39+I41-I40-I42 -> 2548.16 | J43: =J39+J41-J40-J42 -> 2751.0479 | ... N43: =N39+N41-N40-N42 -> 3035.1808 | P43: =N43*(1+$C$4) -> 3080.7086
G46: Discounted CF | H46: =SUMPRODUCT($H$43:$N$43,(1+$C$8)^(-$H$25:$N$25)) -> 16268.685
...

Sheet WACC
B2: Cost of Equity: | F2: Peer group (adjusted) Betas | I2: Net debt | J2: Tax-rate | K2: Equity | L2: D/E | M2: Unlevered Beta
B4: Risk-free rate | C4: 0.025
B5: Equity market premium (Germany): | C5: 0.0423
B6: Debt / Capital Ratio | C6: =C26 -> 0.23731151 | F6: Peer average
B7: Re-levered beta: | C7: 1.157
B10: Cost of Equity (CAPM): | C10: =C4+C7*C5 -> 0.0739411
B12: Cost of Debt:
B13: CDS spread (?Y) | C13: 0.0095
B14: Risk-free rate | C14: =C4 -> 0.025
B15: Pre-tax cost of debt | C15: =C13+C14 -> 0.0345
B16: Tax rate | C16: 0.3
B17: After-tax cost of debt | C17: =C15*(1-C16) -> 0.02415
B20: Cost of Debt: | C20: =C17 -> 0.02415
B22: WACC:
B24: Equity market value | C24: ='Equity Bridge'!C13*'Equity Bridge'!C16 -> 16590
B25: Net debt incl. EV adj. | C25: 5162
B26: Debt / Capital | C26: =C25/(C24+C25) -> 0.23731151
B27: Equity / Capital | C27: =C24/(C24+C25) -> 0.76268849
B28: Target D/E | C28: =C25/C24 -> 0.3111513
B29: Tax rate | C29: 0.3
B31: WACC | C31: =C27*C10+C26*C20*(1-C29) -> 0.060405777

Sheet Equity Bridge
B2: Equity Bridge:
B5: Firm Value | C5: ='FCFF & DCF'!H50 -> 63989.406
B6: + Cash & Securities | C6: 0
B7: - Debt | C7: -5162
B8: - Pensions | C8: -1644
B9: - Minority Interest | C9: -3
B10: - Value of Preferred Stocks | C10: 0
B11: Equity Value | C11: =SUM(C5:C10) -> 57180.406
B13: Number of outstanding shares (in m) | C13: 500
B14: Implied share price | C14: =C11/C13 -> 114.36081
B16: Current share price (30.06.2026) | C16: 33.18
B17: Implied upside | C17: =C14/C16-1 -> 2.4466791

Sheet Multiples
D6: Financial Data | P6: Valuation
C7: EV | D7: EBITDA | H7: Revenue | L7: EBIT | P7: EV/EBITDA | T7: EV/Revenue | X7: EV/EBIT
B8: Company Name | D8: (€M) | H8: (€M) | L8: (€M) | P8: x | T8: x | X8: x
C9: (€M) | D9: LFY | E9: LTM | F9: FY+1 | G9: FY+2 | H9: LFY | I9: LTM | J9: FY+1 | K9: FY+2 | L9: LFY | M9: LTM | N9: FY+1 | O9: FY+2 | P9: LFY | Q9: LTM | R9: FY+1 | S9: FY+2 | T9: LFY | U9: LTM | V9: FY+1 | W9: FY+2 | X9: LFY | Y9: LTM | Z9: FY+1 | AA9: FY+2
B10: Daimler Truck | C10: 23812.8 | D10: 3704 | E10: 2952 | F10: 4643.1 | G10: 5850.5 | H10: 45530 | I10: 44003 | J10: 48726.6 | K10: 52634.1 | L10: 2629 | M10: 1918 | N10: 3551.4 | O10: 4694.9 | P10: =$C10/D10 -> 6.4289417 | Q10: =$C10/E10 -> 8.0666667 | R10: =$C10/F10 -> 5.1286425 | S10: =$C10/G10 -> 4.0702162 | T10: =$C10/H10 -> 0.5230134 | U10: =$C10/I10 -> 0.5411631 | V10: =$C10/J10 -> 0.48870227 | W10: =$C10/K10 -> 0.45242153 | ... AA10: =$C10/O10 -> 5.0720569
B11: Volvo (EUR) | C11: 57869.1 | D11: 6528 | E11: 6505 | F11: 7270 | G11: 8148 | H11: 44351 | I11: 43331 | J11: 45510 | K11: 48895 | L11: 4489 | M11: 4319 | N11: 5221 | O11: 6181 | P11: =$C11/D11 -> 8.8647518 | Q11: =$C11/E11 -> 8.8960953 | R11: =$C11/F11 -> 7.9599862 | S11: =$C11/G11 -> 7.1022459 | T11: =$C11/H11 -> 1.3047981 | U11: =$C11/I11 -> 1.3355127 | V11: =$C11/J11 -> 1.2715689 | W11: =$C11/K11 -> 1.1835382 | ... AA11: =$C11/O11 -> 9.3624171
D14: Financial Data | P14: Implied Enterprise value
C15: EV | D15: EBITDA | H15: Revenue | L15: EBIT | P15: EV/EBITDA | T15: EV/Revenue | X15: EV/EBIT
B16: Company Name | D16: (€M) | H16: (€M) | L16: (€M) | P16: x | T16: x | X16: x
C17: (€M) | D17: LFY | E17: LTM | F17: FY+1 | G17: FY+2 | H17: LFY | I17: LTM | J17: FY+1 | K17: FY+2 | L17: LFY | M17: LTM | N17: FY+1 | O17: FY+2 | P17: LFY | Q17: LTM | R17: FY+1 | S17: FY+2 | T17: LFY | U17: LTM | V17: FY+1 | W17: FY+2 | X17: LFY | Y17: LTM | Z17: FY+1 | AA17: FY+2
B18: Traton | C18: 20759 | D18: 5573 | E18: 5176 | F18: 5802 | G18: 6746 | H18: 44052 | I18: 43675 | J18: 45755 | K18: 48661 | L18: 2426 | M18: 1835 | N18: 3035 | O18: 3984 | P18: =$C18/D18 -> 3.7249237 | Q18: =$C18/E18 -> 4.010626 | R18: =$C18/F18 -> 3.5779042 | S18: =$C18/G18 -> 3.077231 | T18: =$C18/H18 -> 0.47123854 | U18: =$C18/I18 -> 0.47530624 | V18: =$C18/J18 -> 0.45369905 | W18: =$C18/K18 -> 0.42660447 | ... AA18: =$C18/O18 -> 5.2105924
B20: Comparison: Company vs. Peer Group
C21: EV | D21: EBITDA | H21: Revenue | L21: EBIT | P21: EV/EBITDA | T21: EV/Revenue | X21: EV/EBIT
B22: Traton | C22: 20759 | D22: 5573 | E22: 5176 | F22: 5802 | G22: 6746 | H22: 44052 | I22: 43675 | J22: 45755 | K22: 48661 | L22: 2426 | M22: 1835 | N22: 3035 | O22: 3984 | P22: =$C22/D22 -> 3.7249237 | Q22: =$C22/E22 -> 4.010626 | R22: =$C22/F22 -> 3.5779042 | S22: =$C22/G22 -> 3.077231 | T22: =$C22/H22 -> 0.47123854 | U22: =$C22/I22 -> 0.47530624 | V22: =$C22/J22 -> 0.45369905 | W22: =$C22/K22 -> 0.42660447 | ... AA22: =$C22/O22 -> 5.2105924
B23: Quartile 1 | P23: =QUARTILE(P10:P11,1) -> 7.0378942 | Q23: =QUARTILE(Q10:Q11,1) -> 8.2740238 | R23: =QUARTILE(R10:R11,1) -> 5.8364784 | S23: =QUARTILE(S10:S11,1) -> 4.8282237 | T23: =QUARTILE(T10:T11,1) -> 0.71845957 | U23: =QUARTILE(U10:U11,1) -> 0.7397505 | V23: =QUARTILE(V10:V11,1) -> 0.68441892 | W23: =QUARTILE(W10:W11,1) -> 0.6352007 | ... AA23: =QUARTILE(AA10:AA11,1) -> 6.144647
B24: Average | P24: =AVERAGE(P10:P11) -> 7.6468468 | Q24: =AVERAGE(Q10:Q11) -> 8.481381 | R24: =AVERAGE(R10:R11) -> 6.5443144 | S24: =AVERAGE(S10:S11) -> 5.5862311 | T24: =AVERAGE(T10:T11) -> 0.91390574 | U24: =AVERAGE(U10:U11) -> 0.93833789 | V24: =AVERAGE(V10:V11) -> 0.88013558 | W24: =AVERAGE(W10:W11) -> 0.81797986 | ... AA24: =AVERAGE(AA10:AA11) -> 7.217237
B25: Median | P25: =MEDIAN(P10:P11) -> 7.6468468 | Q25: =MEDIAN(Q10:Q11) -> 8.481381 | R25: =MEDIAN(R10:R11) -> 6.5443144 | S25: =MEDIAN(S10:S11) -> 5.5862311 | T25: =MEDIAN(T10:T11) -> 0.91390574 | U25: =MEDIAN(U10:U11) -> 0.93833789 | V25: =MEDIAN(V10:V11) -> 0.88013558 | W25: =MEDIAN(W10:W11) -> 0.81797986 | ... AA25: =MEDIAN(AA10:AA11) -> 7.217237
B26: Quartile 3 | P26: =QUARTILE(P10:P11,3) -> 8.2557993 | Q26: =QUARTILE(Q10:Q11,3) -> 8.6887382 | R26: =QUARTILE(R10:R11,3) -> 7.2521503 | S26: =QUARTILE(S10:S11,3) -> 6.3442385 | T26: =QUARTILE(T10:T11,3) -> 1.1093519 | U26: =QUARTILE(U10:U11,3) -> 1.1369253 | V26: =QUARTILE(V10:V11,3) -> 1.0758522 | W26: =QUARTILE(W10:W11,3) -> 1.000759 | ... AA26: =QUARTILE(AA10:AA11,3) -> 8.289827

Sheet Football-Field
I3: Valuation | J3: low | K3: diff | L3: high
I4: DCF (WACC base to +2%, g base) | J4: ='FCFF & DCF'!$L$59/'Equity Bridge'!$C$13 -> 76.426374 | K4: =L4-J4 -> 37.934437 | L4: ='FCFF & DCF'!$L$57/'Equity Bridge'!$C$13 -> 114.36081
I5: EV/EBITDA (FY+1, peer Q1-Q3) | J5: =(Multiples!R23*Multiples!F18+SUM('Equity Bridge'!$C$6:$C$10))/'Equity Bridge'!$C$13 -> 54.108496 | K5: =L5-J5 -> 16.427456 | L5: =(Multiples!R26*Multiples!F18+SUM('Equity Bridge'!$C$6:$C$10))/'Equity Bridge'!$C$13 -> 70.535952
I6: EV/Revenue (FY+1, peer Q1-Q3) | J6: =(Multiples!V23*Multiples!J18+SUM('Equity Bridge'!$C$6:$C$10))/'Equity Bridge'!$C$13 -> 49.013176 | K6: =L6-J6 -> 35.820062 | L6: =(Multiples!V26*Multiples!J18+SUM('Equity Bridge'!$C$6:$C$10))/'Equity Bridge'!$C$13 -> 84.833238
I7: EV/EBIT (FY+1, peer Q1-Q3) | J7: =(Multiples!Z23*Multiples!N18+SUM('Equity Bridge'!$C$6:$C$10))/'Equity Bridge'!$C$13 -> 33.727198 | K7: =L7-J7 -> 13.289429 | L7: =(Multiples!Z26*Multiples!N18+SUM('Equity Bridge'!$C$6:$C$10))/'Equity Bridge'!$C$13 -> 47.016626
I8: Current price (30.06.2026) | J8: ='Equity Bridge'!$C$16 -> 33.18
I9: Blended fair value (avg midpoint) | J9: =((J4+L4)/2+(J5+L5)/2+(J6+L6)/2+(J7+L7)/2)/4 -> 66.252734
C19: Ev/Ebit non relevant D&A volatile, restructuration expenses due to carve out
