Workbook

Sheet FCFF & DCF
B2: Traton SE — DCF (FCFF) | Valuation date 30.06.2026 | improved reconciliation
B4: Assumptions
B5: Tax rate | C5: 0.3 | E5: Yellow = input | Green = key result
B6: LT growth rate (g) | C6: 0.015
B7: WACC (from WACC tab) | C7: =WACC!C23
B8: Depreciation / Revenue | C8: 0.06
B9: CapEx / Revenue | C9: 0.07
B10: NWC intensity (of ΔRevenue) | C10: 0.15
B11: Valuation date | C11: 30.06.2026
B12: Shares outstanding (m) | C12: 500
B15: Free Cash Flow build-up (EURm) | E15: ← Historical (actual) | K15: Forecast →
B16: Year | C16: 2021 | D16: 2022 | E16: 2023 | F16: 2024 | G16: 2025 | H16: 2026E | I16: 2027E | J16: 2028E | K16: 2029E | L16: 2030E | M16: 2031E | N16: 2032E
B17: Revenue | C17: 30620 | D17: 40335 | E17: 46872 | F17: 47473 | G17: 44051 | H17: 45897 | I17: 48970 | J17: 51418 | K17: 53218 | L17: 54549 | M17: 55640 | N17: 56474
B18: Revenue growth | D18: =D17/C17-1 | E18: =E17/D17-1 | F18: =F17/E17-1 | G18: =G17/F17-1 | H18: =H17/G17-1 | I18: =I17/H17-1 | J18: =J17/I17-1 | K18: =K17/J17-1 | ... N18: =N17/M17-1
B19: EBIT margin | C19: =C20/C17 | D19: =D20/D17 | E19: =E20/E17 | F19: =F20/F17 | G19: =G20/G17 | H19: 0.0664 | I19: 0.0814 | J19: 0.08 | K19: 0.08 | L19: 0.08 | M19: 0.08 | N19: 0.08
B20: EBIT | C20: 502 | D20: 1920 | E20: 3825 | F20: 4417 | G20: 2819 | H20: =H19*H17 | I20: =I19*I17 | J20: =J19*J17 | K20: =K19*K17 | L20: =L19*L17 | M20: =M19*M17 | N20: =N19*N17
B21: Depreciation & amort. | C21: 2729 | D21: 2982 | E21: 2861 | F21: 2975 | G21: 3147 | H21: =$C$8*H17 | I21: =$C$8*I17 | J21: =$C$8*J17 | K21: =$C$8*K17 | L21: =$C$8*L17 | M21: =$C$8*M17 | N21: =$C$8*N17
B22: EBITDA (=EBIT + D&A) | C22: =C20+C21 | D22: =D20+D21 | E22: =E20+E21 | F22: =F20+F21 | G22: =G20+G21 | H22: =H20+H21 | I22: =I20+I21 | J22: =J20+J21 | ... N22: =N20+N21
B23: EBITDA margin | C23: =C22/C17 | D23: =D22/D17 | E23: =E22/E17 | F23: =F22/F17 | G23: =G22/G17 | H23: =H22/H17 | I23: =I22/I17 | J23: =J22/J17 | ... N23: =N22/N17
B24: Taxes on EBIT | H24: =H20*$C$5 | I24: =I20*$C$5 | J24: =J20*$C$5 | K24: =K20*$C$5 | L24: =L20*$C$5 | M24: =M20*$C$5 | N24: =N20*$C$5
B25: NOPAT (=EBIT×(1−t)) | H25: =H20-H24 | I25: =I20-I24 | J25: =J20-J24 | K25: =K20-K24 | L25: =L20-L24 | M25: =M20-M24 | N25: =N20-N24
B26: CapEx | H26: =$C$9*H17 | I26: =$C$9*I17 | J26: =$C$9*J17 | K26: =$C$9*K17 | L26: =$C$9*L17 | M26: =$C$9*M17 | N26: =$C$9*N17
B27: + Depreciation add-back | H27: =H21 | I27: =I21 | J27: =J21 | K27: =K21 | L27: =L21 | M27: =M21 | N27: =N21
B28: − ΔNWC (=intensity×ΔRev) | H28: =$C$10*(H17-G17) | I28: =$C$10*(I17-H17) | J28: =$C$10*(J17-I17) | K28: =$C$10*(K17-J17) | L28: =$C$10*(L17-K17) | M28: =$C$10*(M17-L17) | N28: =$C$10*(N17-M17)
B29: Free Cash Flow to Firm | H29: =H25+H27-H26-H28 | I29: =I25+I27-I26-I28 | J29: =J25+J27-J26-J28 | K29: =K25+K27-K26-K28 | L29: =L25+L27-L26-L28 | M29: =M25+M27-M26-M28 | N29: =N25+N27-N26-N28
B30: Discount period (mid-year) | H30: 0.5 | I30: 1.5 | J30: 2.5 | K30: 3.5 | L30: 4.5 | M30: 5.5 | N30: 6.5
B31: Discount factor | H31: =1/(1+$C$7)^H30 | I31: =1/(1+$C$7)^I30 | J31: =1/(1+$C$7)^J30 | K31: =1/(1+$C$7)^K30 | L31: =1/(1+$C$7)^L30 | M31: =1/(1+$C$7)^M30 | N31: =1/(1+$C$7)^N30
B32: PV of FCFF | H32: =H29*H31 | I32: =I29*I31 | J32: =J29*J31 | K32: =K29*K31 | L32: =L29*L31 | M32: =M29*M31 | N32: =N29*N31
B34: Sum of PV (explicit FCFF) | C34: =SUM(H32:N32)
B35: Terminal value (Gordon, on 2032E) | C35: =N29*(1+C6)/(C7-C6)
B36: PV of terminal value | C36: =C35*N31
B37: Enterprise / Firm Value | C37: =C34+C36
B38: TV as % of Firm Value | C38: =C36/C37
B40: Sensitivity — Firm Value (EURm): WACC (rows) × g (cols)
B41: WACC \ g | C41: 0.005 | D41: 0.01 | E41: 0.015 | F41: 0.02 | G41: 0.025
B42: =C7+-0.01 | C42: =SUMPRODUCT($H$29:$N$29,(1+$B$42)^(-$H$30:$N$30))+($N$29*(1+C$41)/($B$42-C$41))*(1+$B$42)^(-$N$30) | D42: =SUMPRODUCT($H$29:$N$29,(1+$B$42)^(-$H$30:$N$30))+($N$29*(1+D$41)/($B$42-D$41))*(1+$B$42)^(-$N$30) | E42: =SUMPRODUCT($H$29:$N$29,(1+$B$42)^(-$H$30:$N$30))+($N$29*(1+E$41)/($B$42-E$41))*(1+$B$42)^(-$N$30) | F42: =SUMPRODUCT($H$29:$N$29,(1+$B$42)^(-$H$30:$N$30))+($N$29*(1+F$41)/($B$42-F$41))*(1+$B$42)^(-$N$30) | G42: =SUMPRODUCT($H$29:$N$29,(1+$B$42)^(-$H$30:$N$30))+($N$29*(1+G$41)/($B$42-G$41))*(1+$B$42)^(-$N$30)
B43: =C7+-0.005 | C43: =SUMPRODUCT($H$29:$N$29,(1+$B$43)^(-$H$30:$N$30))+($N$29*(1+C$41)/($B$43-C$41))*(1+$B$43)^(-$N$30) | D43: =SUMPRODUCT($H$29:$N$29,(1+$B$43)^(-$H$30:$N$30))+($N$29*(1+D$41)/($B$43-D$41))*(1+$B$43)^(-$N$30) | E43: =SUMPRODUCT($H$29:$N$29,(1+$B$43)^(-$H$30:$N$30))+($N$29*(1+E$41)/($B$43-E$41))*(1+$B$43)^(-$N$30) | F43: =SUMPRODUCT($H$29:$N$29,(1+$B$43)^(-$H$30:$N$30))+($N$29*(1+F$41)/($B$43-F$41))*(1+$B$43)^(-$N$30) | G43: =SUMPRODUCT($H$29:$N$29,(1+$B$43)^(-$H$30:$N$30))+($N$29*(1+G$41)/($B$43-G$41))*(1+$B$43)^(-$N$30)
B44: =C7+0.0 | C44: =SUMPRODUCT($H$29:$N$29,(1+$B$44)^(-$H$30:$N$30))+($N$29*(1+C$41)/($B$44-C$41))*(1+$B$44)^(-$N$30) | D44: =SUMPRODUCT($H$29:$N$29,(1+$B$44)^(-$H$30:$N$30))+($N$29*(1+D$41)/($B$44-D$41))*(1+$B$44)^(-$N$30) | E44: =SUMPRODUCT($H$29:$N$29,(1+$B$44)^(-$H$30:$N$30))+($N$29*(1+E$41)/($B$44-E$41))*(1+$B$44)^(-$N$30) | F44: =SUMPRODUCT($H$29:$N$29,(1+$B$44)^(-$H$30:$N$30))+($N$29*(1+F$41)/($B$44-F$41))*(1+$B$44)^(-$N$30) | G44: =SUMPRODUCT($H$29:$N$29,(1+$B$44)^(-$H$30:$N$30))+($N$29*(1+G$41)/($B$44-G$41))*(1+$B$44)^(-$N$30)
B45: =C7+0.005 | C45: =SUMPRODUCT($H$29:$N$29,(1+$B$45)^(-$H$30:$N$30))+($N$29*(1+C$41)/($B$45-C$41))*(1+$B$45)^(-$N$30) | D45: =SUMPRODUCT($H$29:$N$29,(1+$B$45)^(-$H$30:$N$30))+($N$29*(1+D$41)/($B$45-D$41))*(1+$B$45)^(-$N$30) | E45: =SUMPRODUCT($H$29:$N$29,(1+$B$45)^(-$H$30:$N$30))+($N$29*(1+E$41)/($B$45-E$41))*(1+$B$45)^(-$N$30) | F45: =SUMPRODUCT($H$29:$N$29,(1+$B$45)^(-$H$30:$N$30))+($N$29*(1+F$41)/($B$45-F$41))*(1+$B$45)^(-$N$30) | G45: =SUMPRODUCT($H$29:$N$29,(1+$B$45)^(-$H$30:$N$30))+($N$29*(1+G$41)/($B$45-G$41))*(1+$B$45)^(-$N$30)
B46: =C7+0.01 | C46: =SUMPRODUCT($H$29:$N$29,(1+$B$46)^(-$H$30:$N$30))+($N$29*(1+C$41)/($B$46-C$41))*(1+$B$46)^(-$N$30) | D46: =SUMPRODUCT($H$29:$N$29,(1+$B$46)^(-$H$30:$N$30))+($N$29*(1+D$41)/($B$46-D$41))*(1+$B$46)^(-$N$30) | E46: =SUMPRODUCT($H$29:$N$29,(1+$B$46)^(-$H$30:$N$30))+($N$29*(1+E$41)/($B$46-E$41))*(1+$B$46)^(-$N$30) | F46: =SUMPRODUCT($H$29:$N$29,(1+$B$46)^(-$H$30:$N$30))+($N$29*(1+F$41)/($B$46-F$41))*(1+$B$46)^(-$N$30) | G46: =SUMPRODUCT($H$29:$N$29,(1+$B$46)^(-$H$30:$N$30))+($N$29*(1+G$41)/($B$46-G$41))*(1+$B$46)^(-$N$30)
...

Sheet WACC
B2: WACC — live calculation (single tax shield)
B4: Cost of Equity (CAPM) | E4: Peer unlevered betas
B5: Risk-free rate (10Y Bund) | C5: 0.035 | E5: Daimler Truck | F5: 1.089
B6: Equity market premium (DE) | C6: 0.0423 | E6: Volvo | F6: 0.921
B7: Peer unlevered beta (avg) | C7: =AVERAGE(F5:F6) | E7: (already unlevered peer betas)
B8: Tax rate | C8: 0.3
B9: Net industrial debt (EV−MCap) | C9: 4539
B10: Equity market value (MCap) | C10: 16590
B11: Target D/E | C11: =C9/C10
B12: Re-levered beta βL=βU·(1+(1−t)·D/E) | C12: =C7*(1+(1-C8)*C11)
B13: Cost of equity Ke=rf+βL·MRP | C13: =C5+C12*C6
B15: Cost of Debt
B16: CDS spread | C16: 0.012
B17: Pre-tax cost of debt (rf+CDS) | C17: =C5+C16
B18: After-tax cost of debt ×(1−t) | C18: =C17*(1-C8)
B20: WACC
B21: Debt / Capital | C21: =C9/(C9+C10)
B22: Equity / Capital | C22: =C10/(C9+C10)
B23: WACC = E/V·Ke + D/V·Kd(1−t) | C23: =C22*C13+C21*C18 | E23: ← no double tax shield (C18 already after-tax)

Sheet Equity Bridge
B2: Equity Bridge — industrial net debt basis
B4: Firm / Enterprise Value | C4: ='FCFF & DCF'!C37
B5: + Cash (in industrial net debt) | C5: 0
B6: − Net industrial debt (EV−MCap) | C6: 4539
B7: − Pension provisions | C7: 1590
B8: − Minority interest | C8: 3
B9: − Preferred stock | C9: 0
B10: Equity Value | C10: =C4+C5-C6-C7-C8-C9
B12: Shares outstanding (m) | C12: 500
B13: Implied share price (€) | C13: =C10/C12
B14: Current price 30.06.2026 (€) | C14: 33.18
B15: Implied upside | C15: =C13/C14-1
B17: Note: Gross debt ≈ EUR 28,799m, but ~22bn is captive Financial-Services debt
B18: matched by financing receivables → use industrial net debt (EV−MCap = 4,539). See A.1.

Sheet Multiples
B2: Trading Multiples — peer group (FY+1 focus)
B4: Note: Volvo figures in SEK; ratios are dimensionless so comparable.
B6: Company | C6: EV | D6: EBITDA FY+1 | E6: Revenue FY+1 | F6: EBIT FY+1 | G6: EV/EBITDA | H6: EV/Revenue | I6: EV/EBIT
B7: Daimler Truck | C7: 24731 | D7: 4643 | E7: 48727 | F7: 3551 | G7: =C7/D7 | H7: =C7/E7 | I7: =C7/F7
B8: Volvo (SEK) | C8: 639956 | D8: 78548 | E8: 491731 | F8: 56412 | G8: =C8/D8 | H8: =C8/E8 | I8: =C8/F8
B9: Median (peer) | G9: =MEDIAN(G7:G8) | H9: =MEDIAN(H7:H8) | I9: =MEDIAN(I7:I8)
B10: Min (peer) | G10: =MIN(G7:G8) | H10: =MIN(H7:H8) | I10: =MIN(I7:I8)
B11: Max (peer) | G11: =MAX(G7:G8) | H11: =MAX(H7:H8) | I11: =MAX(I7:I8)
B13: Traton metric (FY+1 2026E)
B14: Traton | D14: 5719 | E14: 45897 | F14: 3049
B16: Implied valuation (median peer × Traton FY+1)
B17: Method | C17: Implied EV | D17: Implied Equity | E17: Implied Price | F17: Upside
B18: EV/EBITDA | C18: =G9*D14 | D18: =C18-('Equity Bridge'!$C$6+'Equity Bridge'!$C$7+'Equity Bridge'!$C$8) | E18: =D18/'Equity Bridge'!$C$12 | F18: =E18/'Equity Bridge'!$C$14-1
B19: EV/Revenue | C19: =H9*E14 | D19: =C19-('Equity Bridge'!$C$6+'Equity Bridge'!$C$7+'Equity Bridge'!$C$8) | E19: =D19/'Equity Bridge'!$C$12 | F19: =E19/'Equity Bridge'!$C$14-1
B20: EV/EBIT | C20: =I9*F14 | D20: =C20-('Equity Bridge'!$C$6+'Equity Bridge'!$C$7+'Equity Bridge'!$C$8) | E20: =D20/'Equity Bridge'!$C$12 | F20: =E20/'Equity Bridge'!$C$14-1

Sheet Football-Field
B2: Football Field — valuation range (€/share)
B4: Method | C4: Low | D4: Δ | E4: High
B5: DCF (WACC ±0.5%, g 1.5%) | C5: ='FCFF & DCF'!E53 | D5: =E5-C5 | E5: ='FCFF & DCF'!E51
B6: EV/EBITDA (peer min–max) | C6: =(Multiples!G10*Multiples!D14-('Equity Bridge'!$C$6+'Equity Bridge'!$C$7+'Equity Bridge'!$C$8))/'Equity Bridge'!$C$12 | D6: =E6-C6 | E6: =(Multiples!G11*Multiples!D14-('Equity Bridge'!$C$6+'Equity Bridge'!$C$7+'Equity Bridge'!$C$8))/'Equity Bridge'!$C$12
B7: EV/Revenue (peer min–max) | C7: =(Multiples!H10*Multiples!E14-('Equity Bridge'!$C$6+'Equity Bridge'!$C$7+'Equity Bridge'!$C$8))/'Equity Bridge'!$C$12 | D7: =E7-C7 | E7: =(Multiples!H11*Multiples!E14-('Equity Bridge'!$C$6+'Equity Bridge'!$C$7+'Equity Bridge'!$C$8))/'Equity Bridge'!$C$12
B8: EV/EBIT (peer min–max) | C8: =(Multiples!I10*Multiples!F14-('Equity Bridge'!$C$6+'Equity Bridge'!$C$7+'Equity Bridge'!$C$8))/'Equity Bridge'!$C$12 | D8: =E8-C8 | E8: =(Multiples!I11*Multiples!F14-('Equity Bridge'!$C$6+'Equity Bridge'!$C$7+'Equity Bridge'!$C$8))/'Equity Bridge'!$C$12
B9: Current price 30.06.2026 | C9: ='Equity Bridge'!C14
B10: Blended fair value (avg midpoint) | C10: =((C5+E5)/2+(C6+E6)/2+(C7+E7)/2+(C8+E8)/2)/4

Sheet Changelog
B2: What changed vs. the two existing models
B4: # | C4: Issue | D4: Team model | E4: Julia FINAL | F4: This model (fix)
B5: 1 | C5: WACC tax shield | D5: 6.04% — (1−t) applied twice on Kd | E5: 7.43% but hardcoded | F5: 7.43% live formula, single tax shield
B6: 2 | C6: CapEx vs Depreciation | D6: CapEx 6% < Dep 7.16% → base shrinks | E6: CapEx = Dep (neutral) | F6: CapEx 7% > Dep 6% → net reinvest 1% rev, consistent w/ g
B7: 3 | C7: EBITDA build-up | D7: ok | E7: SG&A jump → EBITDA +10% vs consensus | F7: EBITDA = EBIT + D&A, margin ≈ consensus 12.5%
B8: 4 | C8: ΔNWC | D8: 1% of ΔRevenue (too low) | E8: 1.6% of Revenue level (too high) | F8: 15% of ΔRevenue (NWC intensity)
B9: 5 | C9: Discounting | D9: period 0 for 2026E | E9: period 0 for 2026E | F9: mid-year convention (0.5…6.5) for 30.06 date
B10: 6 | C10: Equity bridge | D10: −5,162 (undocumented) | E10: −4,539 industrial net debt (good) | F10: kept: −4,539 industrial net debt (A.1)
B11: 7 | C11: EBIT line | D11: hardcoded | E11: hardcoded | F11: =EBIT margin × Revenue (live)
B12: 8 | C12: Football field | D12: mixed range defs | E12: peer min–max only | F12: peer min–max labelled + DCF WACC band
B14: Result: implied price lands ~€63 (base), vs Julia €61 and Team €114.
B15: Julia's model was sound; Team's €114 was inflated by the WACC bug, near-zero ΔNWC and shrinking capital base.
